<?xml version="1.0"?>
<robot name="bipedal" >


  <link name="base_link">

    <visual>
      <geometry>
        <box size="0.15 0.15 0.15"/>
      </geometry>
      <material name="blue">
        <color rgba="0 0 .8 1"/>
      </material>
    </visual>

    <collision>
      <geometry>
        <box size="0.15 0.15 0.15"/>
      </geometry>
    </collision>

    <inertial>
      <mass value="4."/>
      <inertia ixx="0.015"  ixy="0"  ixz="0" iyy="0.015" iyz="0" izz="0.015" />
    </inertial>
  </link>


  <link name="left_leg">

    <visual>
      <geometry>
        <box size="0.075 0.075 0.15"/>
      </geometry>
      <origin rpy="0 0 0" xyz="0 0.0375 -0.075"/>
      <material name="white">
        <color rgba="1 1 1 1"/>
      </material>
    </visual>

    <collision>
      <geometry>
        <box size="0.075 0.075 0.15"/>
      </geometry>
     <origin rpy="0 0 0" xyz="0 0.0375 -0.075"/>
    </collision>

    <inertial>
      <mass value="0.2"/>
      <inertia ixx="0.00047"  ixy="0"  ixz="0" iyy="0.00047" iyz="0" izz="0.00019" />
    </inertial>
  </link>


  <joint name="base_to_left_leg" type="revolute">
    <axis xyz="1 0 0"/>
    <limit effort="20" lower="-0.785" upper="0.785" velocity="2"/>
    <origin rpy="0 0.7854 0" xyz="-0.125 0.075 0"/>
    <parent link="base_link"/>
    <child link="left_leg"/>
  </joint>

  <link name="left_thigh">

    <visual>
      <geometry>
        <box size="0.075 0.075 0.15"/>
      </geometry>
      <origin rpy="0 0 0" xyz="0.0375 0.0375 -0.075"/>
      <material name="white">
        <color rgba="1 1 1 1"/>
      </material>
    </visual>

    <collision>
      <geometry>
        <box size="0.075 0.075 0.15"/>
      </geometry>
     <origin rpy="0 0 0" xyz="0.0375 0.0375 -0.075"/>
    </collision>

    <inertial>
      <mass value="0.2"/>
      <inertia ixx="0.00047"  ixy="0"  ixz="0" iyy="0.00047" iyz="0" izz="0.00019" />
    </inertial>
  </link>

  <joint name="left_leg_to_thigh" type="revolute">
    <axis xyz="0 1 0"/>
    <limit effort="20" lower="-0.785" upper="0.785" velocity="2"/>
    <origin rpy="0 0 0" xyz="0.0375 0 -0.15"/>
    <parent link="left_leg"/>
    <child link="left_thigh"/>
  </joint>
  <link name="left_bicep">

    <visual>
      <geometry>
        <box size="0.075 0.075 0.3"/>
      </geometry>
       <origin rpy="0 0 0" xyz="-0.0375 0.0375 -0.15"/>
      <material name="white"/>
    </visual>

    <collision>
      <geometry>
        <box size="0.075 0.075 0.3"/>
      </geometry>
       <origin rpy="0 0 0" xyz="-0.0375 0.0375 -0.15"/>
    </collision>

    <inertial>
      <mass value="0.2"/>
      <inertia ixx="0.00159"  ixy="0"  ixz="0" iyy="0.00159" iyz="0" izz="0.00019" />
    </inertial>
  </link>


  <joint name="left_bicep_joint" type="revolute">
    <axis xyz="0 1 0"/>
    <limit effort="20" lower="-0.785" upper="0.785" velocity="2"/>
    <origin rpy="0 -1.5708 0" xyz="0.075 0 -0.15"/>
    <parent link="left_thigh"/>
    <child link="left_bicep"/>
  </joint>


  <link name="left_feet">

    <visual>
      <geometry>
        <box size="0.2 0.05 0.02"/>
      </geometry>
       <origin rpy="0. 0. 0." xyz="0.02 0 -0.01"/>
      <material name="white"/>
    </visual>

    <collision>
      <geometry>
        <box size="0.15 0.1 0.02"/>
      </geometry>
       <origin rpy="0 0 0" xyz="0.02 0 -0.01"/>
    </collision>

    <inertial>
      <mass value="0.1"/>
      <inertia ixx="0.00005"  ixy="0"  ixz="0" iyy="0.00013" iyz="0" izz="0.00018" />
    </inertial>
  </link>


  <joint name="left_feet_joint" type="revolute">
    <axis xyz="0 1 0"/>
    <limit effort="20" lower="-0.785" upper="0.785" velocity="2"/>
    <origin rpy="0 0.7854 0" xyz="-0.1 0.0375 -0.35"/>
    <parent link="left_bicep"/>
    <child link="left_feet"/>
  </joint>


  <link name="right_leg">

    <visual>
      <geometry>
        <box size="0.075 0.075 0.15"/>
      </geometry>
      <origin rpy="0 0 0" xyz="0 -0.0375 -0.075"/>
      <material name="white">
        <color rgba="1 1 1 1"/>
      </material>
    </visual>

    <collision>
      <geometry>
        <box size="0.075 0.075 0.15"/>
      </geometry>
     <origin rpy="0 0 0" xyz="0 -0.0375 -0.075"/>
    </collision>

    <inertial>
      <mass value="0.2"/>
      <inertia ixx="0.00047"  ixy="0"  ixz="0" iyy="0.00047" iyz="0" izz="0.00019" />
    </inertial>
  </link>


  <joint name="base_to_right_leg" type="revolute">
    <axis xyz="1 0 0"/>
    <limit effort="20" lower="-0.785" upper="0.785" velocity="2"/>
    <origin rpy="0 0.7854 0" xyz="-0.125 -0.075 0"/>
    <parent link="base_link"/>
    <child link="right_leg"/>
  </joint>

  <link name="right_thigh">

    <visual>
      <geometry>
        <box size="0.075 0.075 0.15"/>
      </geometry>
      <origin rpy="0 0 0" xyz="0.0375 -0.0375 -0.075"/>
      <material name="white">
        <color rgba="1 1 1 1"/>
      </material>
    </visual>

    <collision>
      <geometry>
        <box size="0.075 0.075 0.15"/>
      </geometry>
     <origin rpy="0 0 0" xyz="0.0375 -0.0375 -0.075"/>
    </collision>

    <inertial>
      <mass value="0.2"/>
      <inertia ixx="0.00047"  ixy="0"  ixz="0" iyy="0.00047" iyz="0" izz="0.00019" />
    </inertial>
  </link>
  
  <joint name="right_leg_to_thigh" type="revolute">
    <axis xyz="0 1 0"/>
    <limit effort="20" lower="-0.785" upper="0.785" velocity="2"/>
    <origin rpy="0 0 0" xyz="0.0375 0 -0.15"/>
    <parent link="right_leg"/>
    <child link="right_thigh"/>
  </joint>

  <link name="right_bicep">

    <visual>
      <geometry>
        <box size="0.075 0.075 0.3"/>
      </geometry>
       <origin rpy="0 0 0" xyz="-0.0375 -0.0375 -0.15"/>
      <material name="white"/>
    </visual>

    <collision>
      <geometry>
        <box size="0.075 0.075 0.3"/>
      </geometry>
       <origin rpy="0 0 0" xyz="-0.0375 -0.0375 -0.15"/>
    </collision>

    <inertial>
      <mass value="0.2"/>
      <inertia ixx="0.00159"  ixy="0"  ixz="0" iyy="0.00159" iyz="0" izz="0.00019" />
    </inertial>
  </link>

  <joint name="right_bicep_joint" type="revolute">
    <axis xyz="0 1 0"/>
    <limit effort="20" lower="-0.785" upper="0.785" velocity="2"/>
    <origin rpy="0 -1.5708 0" xyz="0.075 0 -0.15"/>
    <parent link="right_thigh"/>
    <child link="right_bicep"/>
  </joint>

  
 <link name="right_feet">

    <visual>
      <geometry>
        <box size="0.2 0.05 0.02"/>
      </geometry>
       <origin rpy="0. 0. 0." xyz="0.02 0 -0.01"/>
      <material name="white"/>
    </visual>

    <collision>
      <geometry>
        <box size="0.15 0.1 0.02"/>
      </geometry>
       <origin rpy="0 0 0" xyz="0.02 0 -0.01"/>
    </collision>

    <inertial>
      <mass value="0.1"/>
      <inertia ixx="0.00005"  ixy="0"  ixz="0" iyy="0.00013" iyz="0" izz="0.00018" />
    </inertial>
  </link>


  <joint name="right_feet_joint" type="revolute">
    <axis xyz="0 1 0"/>
    <limit effort="20" lower="-0.785" upper="0.785" velocity="2"/>
    <origin rpy="0 0.7854 0" xyz="-0.1 -0.0375 -0.35"/>
    <parent link="right_bicep"/>
    <child link="right_feet"/>
  </joint>
</robot>